try{
    throw new Error('Lançando nossa primeira exceção')
} catch (erro) {
    console.log(erro)
}